Workbook
Name KPI_ACC: KPIs!$B$2:$B$11
Name KPI_HR: KPIs!$B$12:$B$21
Name KPI_محاسب: KPIs!$B$2:$B$11
Name KPI_منسق: KPIs!$B$12:$B$21
Name KPI_منسق_موارد_بشرية: KPIs!$B$12:$B$21

Sheet EMPLOYEES
A1: EmployeeName | B1: JobTitle | C1: القسم | D1: اسم المقيم
A2: زياد سالم حمدان المعايعه | B2: مدير الموارد البشرية | C2: الموارد البشرية | D2: ناصر فنون
A3: احمد محمد زياد شعبان فنون | B3: مدير اسطول | C3: العمليات | D3: تامر فنون
A4: تامر طاهر محمد يسري فنون | B4: مدير مشروع | C4: العمليات | D4: جمال فنون
A5: علي سالم محمد بني عواد | B5: مشرف سلامة عامة | C5: العمليات | D5: تامر فنون
A6: فايز احمد موسى اصليح | B6: مندوب | C6: العمليات | D6: تامر فنون
A7: عمر ناصر محمد يسري فنون | B7: ضابط مشتريات | C7: العمليات | D7: تامر فنون
A8: يزن صالح محمد العامودي | B8: ضابط سلامة وصحة عامة وتتبع | C8: العمليات | D8: تامر فنون
A9: وائل ضيف الله سليمان ابو اثنين | B9: حارس | C9: العمليات | D9: تامر فنون
A10: جمال ياسر محمود الخطيب | B10: مندوب | C10: العمليات | D10: تامر فنون
A11: زكي محمد بدوي حسن البزلميط | B11: معقب معاملات | C11: العمليات | D11: تامر فنون
A12: مصباح احمد مصباح الشريف | B12: مندوب | C12: العمليات | D12: تامر فنون
... A50: جلال جمال محمد يسري فنون | B50: مدير جودة وسلامة عامة وبيئة | C50: السلامه العامه | D50: تامر فنون

Sheet KPIs
A1: JobTitle | B1: KPI_Name | C1: Weight
A2: محاسب | B2: الالتزام بإغلاق الفترات المالية ضمن الإطار الزمني المحدد | C2: 10
A3: محاسب | B3: تنظيم وأرشفة المستندات المالية وفق معايير الرقابة المعتمدة | C3: 6
A4: محاسب | B4: الالتزام بأنظمة الرقابة الداخلية والسياسات المالية | C4: 9
A5: محاسب | B5: دقة العمليات المحاسبية وتقليل نسبة الأخطاء | C5: 9
A6: محاسب | B6: سرعة ودقة تسجيل القيود والمطابقات البنكية ومعالجة فواتير الموردين | C6: 9
A7: محاسب | B7: جودة إعداد وتحليل التقارير المالية ورفعها في الوقت المحدد | C7: 9
A8: محاسب | B8: الاستجابة الفعّالة للمهام الإدارية وحل الخلافات المالية | C8: 7
A9: محاسب | B9: التواصل المهني مع الإدارة والأقسام الأخرى وتعزيز التعاون الداخلي | C9: 7
A10: محاسب | B10: التعامل المهني مع العملاء والرد على الاستفسارات المالية بكفاءة | C10: 7
A11: محاسب | B11: وضوح ودقة توصيل المعلومات المالية للموظفين والجهات ذات العلاقة | C11: 7 | D11: =SUM(C2:C11) -> 80
A12: منسق موارد بشرية | B12: معرفة وتطبيق اللوائح والقوانين (قانون العمل والضمان) | C12: 10
A13: منسق موارد بشرية | B13: إدارة وتنظيم الملفات والسجلات وسهولة الرجوع إليها | C13: 9
A14: منسق موارد بشرية | B14: السرعة والدقة والإنتاجية في إنجاز العمل | C14: 9
A15: منسق موارد بشرية | B15: التحليل وإعداد التقارير بدقة واحترافية | C15: 8
A16: منسق موارد بشرية | B16: الالتزام بأخلاقيات العمل والحياد والمسؤولية | C16: 8
A17: منسق موارد بشرية | B17: الالتزام بمتطلبات السلامة العامة داخل بيئة العمل | C17: 7
A18: منسق موارد بشرية | B18: المبادرة واقتراح التحسينات وحل المشكلات | C18: 8
A19: منسق موارد بشرية | B19: التواصل الفعّال والتعامل المهني (رؤساء، زملاء، عملاء، موظفين جدد) | C19: 7
A20: منسق موارد بشرية | B20: تحمل ضغط العمل وتنظيم الأولويات وتحمل النتائج | C20: 7
A21: منسق موارد بشرية | B21: نقل المعرفة وتدريب الآخرين ودعم الفريق | C21: 7 | D21: =SUM(C12:C21) -> 80
A22: مدير اسطول | B22: دقة تسجيل حركة الشاحنات وتنظيم مواقفها | C22: 10
A23: مدير اسطول | B23: جاهزية الشاحنات ومتابعة حالتها الفنية والوثائق القانونية | C23: 10
A24: مدير اسطول | B24: إدارة السائقين (الدوام، توزيع المهام، التواصل والمتابعة) | C24: 10
A25: مدير اسطول | B25: الالتزام بالسلامة والصحة المهنية والإبلاغ عن الحوادث والمخالفات | C25: 10
A26: مدير اسطول | B26: الرقابة على استهلاك الوقود والعدادات والقيادة الاقتصادية وتقليل الهدر | C26: 10
A27: مدير اسطول | B27: تنفيذ الجولات الميدانية ومتابعة الأداء على خطوط السير | C27: 7
A28: مدير اسطول | B28: إعداد التقارير الدورية بدقة وفي الوقت المحدد | C28: 6
A29: مدير اسطول | B29: التنظيم والعمل تحت الضغط وحسن التصرف والالتزام بالتوجيهات | C29: 6
A30: مدير اسطول | B30: التعاون والتنسيق مع الإدارات الأخرى وتقديم خدمة مهنية للموظفين | C30: 6
A31: مدير اسطول | B31: مهارات التفاوض والإقناع والإيجابية في التعامل | C31: 5 | D31: =SUM(C22:C31) -> 80
A32: مدخل بيانات | B32: دقة إدخال البيانات | C32: 10
A33: مدخل بيانات | B33: السرعة في الإنجاز | C33: 9
A34: مدخل بيانات | B34: التدقيق ومراجعة البيانات | C34: 9
A35: مدخل بيانات | B35: الالتزام بالعمليات المالية | C35: 8
A36: مدخل بيانات | B36: الالتزام والانضباط | C36: 8
A37: مدخل بيانات | B37: القدرة على العمل تحت الضغط | C37: 8
A38: مدخل بيانات | B38: تنظيم الملفات والسجلات | C38: 8
A39: مدخل بيانات | B39: التعامل مع الإدارة | C39: 7
A40: مدخل بيانات | B40: التعاون مع الموظفين | C40: 7
...

Sheet MONTHS
A1: Month
A2: Jan
A3: Feb
A4: Mar
A5: Apr
A6: May
A7: Jun
A8: Jul
A9: Aug
A10: Sep
A11: Oct
A12: Nov
A13: Dec

Sheet INPUT
A1: سنة التقييم | B1: 2025 | E1: YEAR
A2: اسم الموظف | B2: ايهاب محمد خميس حمد | E2: 2025 | I2: 2025
A3: الشهر | B3: Feb | I3: 2026
A4: اسم المقيم | B4: زياد المعايعة
A5: القسم | B5: الموارد البشرية | I5: 2027
A6: وظيفة العامل | B6: =_xlfn.XLOOKUP(B2, EMPLOYEES!A:A, EMPLOYEES!B:B) -> منسق موارد بشرية
B7: =IF(B7="","", IF(B7<60,"Weak", IF(B7<70,"Acceptable", IF(B7<85,"Good","Very Good")))) -> Very Good | C7: التقييم الفعلي للموظف
A8: KPI_Name | B8: Weight | C8: KPI_%
A9: {=_xlfn._xlws.FILTER(KPIs!B:B, KPIs!A:A = B6)} -> معرفة وتطبيق اللوائح والقوانين (قانون العمل والضمان) | B9: {=_xlfn.XLOOKUP(_xlfn.ANCHORARRAY(A9), KPIs!B:B, KPIs!C:C)} -> 10
A10: إدارة وتنظيم الملفات والسجلات وسهولة الرجوع إليها | B10: 9
A11: السرعة والدقة والإنتاجية في إنجاز العمل | B11: 9
A12: التحليل وإعداد التقارير بدقة واحترافية | B12: 8
A13: الالتزام بأخلاقيات العمل والحياد والمسؤولية | B13: 8
A14: الالتزام بمتطلبات السلامة العامة داخل بيئة العمل | B14: 7
A15: المبادرة واقتراح التحسينات وحل المشكلات | B15: 8
A16: التواصل الفعّال والتعامل المهني (رؤساء، زملاء، عملاء، موظفين جدد) | B16: 7
A17: تحمل ضغط العمل وتنظيم الأولويات وتحمل النتائج | B17: 7
A18: نقل المعرفة وتدريب الآخرين ودعم الفريق | B18: 7

Sheet AUTO_MONTHLY
A1: EmployeeName | B1: Month | C1: Monthly_score | D1: YEAR
A2: احمد محمد زياد شعبان فنون | B2: January | C2: =IFERROR( SUMIFS( DATA!$E:$E, DATA!$A:$A, $A2, DATA!$B:$B, $B2 ) / 100,0) -> 0 | D2: =INPUT!$E$2 -> 2025
A3: احمد محمد زياد شعبان فنون | B3: February | C3: =IFERROR( SUMIFS( DATA!$E:$E, DATA!$A:$A, $A3, DATA!$B:$B, $B3 ) / 100,0) -> 0 | D3: =INPUT!$E$2 -> 2025
A4: احمد محمد زياد شعبان فنون | B4: March | C4: =IFERROR( SUMIFS( DATA!$E:$E, DATA!$A:$A, $A4, DATA!$B:$B, $B4 ) / 100,0) -> 0 | D4: =INPUT!$E$2 -> 2025
A5: احمد محمد زياد شعبان فنون | B5: April | C5: =IFERROR( SUMIFS( DATA!$E:$E, DATA!$A:$A, $A5, DATA!$B:$B, $B5 ) / 100,0) -> 0 | D5: =INPUT!$E$2 -> 2025
A6: احمد محمد زياد شعبان فنون | B6: May | C6: =IFERROR( SUMIFS( DATA!$E:$E, DATA!$A:$A, $A6, DATA!$B:$B, $B6 ) / 100,0) -> 0 | D6: =INPUT!$E$2 -> 2025
A7: احمد محمد زياد شعبان فنون | B7: June | C7: =IFERROR( SUMIFS( DATA!$E:$E, DATA!$A:$A, $A7, DATA!$B:$B, $B7 ) / 100,0) -> 0 | D7: =INPUT!$E$2 -> 2025
A8: احمد محمد زياد شعبان فنون | B8: July | C8: =IFERROR( SUMIFS( DATA!$E:$E, DATA!$A:$A, $A8, DATA!$B:$B, $B8 ) / 100,0) -> 0 | D8: =INPUT!$E$2 -> 2025
A9: احمد محمد زياد شعبان فنون | B9: August | C9: =IFERROR( SUMIFS( DATA!$E:$E, DATA!$A:$A, $A9, DATA!$B:$B, $B9 ) / 100,0) -> 0 | D9: =INPUT!$E$2 -> 2025
A10: احمد محمد زياد شعبان فنون | B10: September | C10: =IFERROR( SUMIFS( DATA!$E:$E, DATA!$A:$A, $A10, DATA!$B:$B, $B10 ) / 100,0) -> 0 | D10: =INPUT!$E$2 -> 2025
A11: احمد محمد زياد شعبان فنون | B11: October | C11: =IFERROR( SUMIFS( DATA!$E:$E, DATA!$A:$A, $A11, DATA!$B:$B, $B11 ) / 100,0) -> 0 | D11: =INPUT!$E$2 -> 2025
A12: احمد محمد زياد شعبان فنون | B12: November | C12: =IFERROR( SUMIFS( DATA!$E:$E, DATA!$A:$A, $A12, DATA!$B:$B, $B12 ) / 100,0) -> 0 | D12: =INPUT!$E$2 -> 2025
A13: احمد محمد زياد شعبان فنون | B13: December | C13: =IFERROR( SUMIFS( DATA!$E:$E, DATA!$A:$A, $A13, DATA!$B:$B, $B13 ) / 100,0) -> 0 | D13: =INPUT!$E$2 -> 2025
A14: ايهاب محمد خميس حمد | B14: Jan | C14: =IFERROR( SUMIFS( DATA!$E:$E, DATA!$A:$A, $A14, DATA!$B:$B, $B14 ) / 100, 0) -> 0.8 | D14: =INPUT!$E$2 -> 2025
A15: ايهاب محمد خميس حمد | B15: February | C15: =IFERROR( SUMIFS( DATA!$E:$E, DATA!$A:$A, $A15, DATA!$B:$B, $B15 ) / 100, 0) -> 0 | D15: =INPUT!$E$2 -> 2025
A16: ايهاب محمد خميس حمد | B16: March | C16: =IFERROR( SUMIFS( DATA!$E:$E, DATA!$A:$A, $A16, DATA!$B:$B, $B16 ) / 100, 0) -> 0 | D16: =INPUT!$E$2 -> 2025
A17: ايهاب محمد خميس حمد | B17: April | C17: =IFERROR( SUMIFS( DATA!$E:$E, DATA!$A:$A, $A17, DATA!$B:$B, $B17 ) / 100, 0) -> 0 | D17: =INPUT!$E$2 -> 2025
A18: ايهاب محمد خميس حمد | B18: May | C18: =IFERROR( SUMIFS( DATA!$E:$E, DATA!$A:$A, $A18, DATA!$B:$B, $B18 ) / 100, 0) -> 0 | D18: =INPUT!$E$2 -> 2025
A19: ايهاب محمد خميس حمد | B19: June | C19: =IFERROR( SUMIFS( DATA!$E:$E, DATA!$A:$A, $A19, DATA!$B:$B, $B19 ) / 100, 0) -> 0 | D19: =INPUT!$E$2 -> 2025
A20: ايهاب محمد خميس حمد | B20: July | C20: =IFERROR( SUMIFS( DATA!$E:$E, DATA!$A:$A, $A20, DATA!$B:$B, $B20 ) / 100, 0) -> 0 | D20: =INPUT!$E$2 -> 2025
A21: ايهاب محمد خميس حمد | B21: August | C21: =IFERROR( SUMIFS( DATA!$E:$E, DATA!$A:$A, $A21, DATA!$B:$B, $B21 ) / 100, 0) -> 0 | D21: =INPUT!$E$2 -> 2025
A22: ايهاب محمد خميس حمد | B22: September | C22: =IFERROR( SUMIFS( DATA!$E:$E, DATA!$A:$A, $A22, DATA!$B:$B, $B22 ) / 100, 0) -> 0 | D22: =INPUT!$E$2 -> 2025
A23: ايهاب محمد خميس حمد | B23: October | C23: =IFERROR( SUMIFS( DATA!$E:$E, DATA!$A:$A, $A23, DATA!$B:$B, $B23 ) / 100, 0) -> 0 | D23: =INPUT!$E$2 -> 2025
A24: ايهاب محمد خميس حمد | B24: November | C24: =IFERROR( SUMIFS( DATA!$E:$E, DATA!$A:$A, $A24, DATA!$B:$B, $B24 ) / 100, 0) -> 0 | D24: =INPUT!$E$2 -> 2025
A25: ايهاب محمد خميس حمد | B25: December | C25: =IFERROR( SUMIFS( DATA!$E:$E, DATA!$A:$A, $A25, DATA!$B:$B, $B25 ) / 100, 0) -> 0 | D25: =INPUT!$E$2 -> 2025
... A30: خلدون عامر حامد الكسيح | B30: Jan | C30: =IFERROR( SUMIFS( DATA!$E:$E, DATA!$A:$A, $A30, DATA!$B:$B, $B30 ) / 100, 0) -> 0 | D30: =INPUT!$E$2 -> 2025
C31: =IFERROR( SUMIFS( DATA!$E:$E, DATA!$A:$A, $A31, DATA!$B:$B, $B31 ) / 100, 0) -> 0 | D31: =INPUT!$E$2 -> 2025
C32: =IFERROR( SUMIFS( DATA!$E:$E, DATA!$A:$A, $A32, DATA!$B:$B, $B32 ) / 100, 0) -> 0 | D32: =INPUT!$E$2 -> 2025
C33: =IFERROR( SUMIFS( DATA!$E:$E, DATA!$A:$A, $A33, DATA!$B:$B, $B33 ) / 100, 0) -> 0 | D33: =INPUT!$E$2 -> 2025
C34: =IFERROR( SUMIFS( DATA!$E:$E, DATA!$A:$A, $A34, DATA!$B:$B, $B34 ) / 100, 0) -> 0 | D34: =INPUT!$E$2 -> 2025
C35: =IFERROR( SUMIFS( DATA!$E:$E, DATA!$A:$A, $A35, DATA!$B:$B, $B35 ) / 100, 0) -> 0 | D35: =INPUT!$E$2 -> 2025
C36: =IFERROR( SUMIFS( DATA!$E:$E, DATA!$A:$A, $A36, DATA!$B:$B, $B36 ) / 100, 0) -> 0 | D36: =INPUT!$E$2 -> 2025
C37: =IFERROR( SUMIFS( DATA!$E:$E, DATA!$A:$A, $A37, DATA!$B:$B, $B37 ) / 100, 0) -> 0 | D37: =INPUT!$E$2 -> 2025
C38: =IFERROR( SUMIFS( DATA!$E:$E, DATA!$A:$A, $A38, DATA!$B:$B, $B38 ) / 100, 0) -> 0 | D38: =INPUT!$E$2 -> 2025
C39: =IFERROR( SUMIFS( DATA!$E:$E, DATA!$A:$A, $A39, DATA!$B:$B, $B39 ) / 100, 0) -> 0 | D39: =INPUT!$E$2 -> 2025
C40: =IFERROR( SUMIFS( DATA!$E:$E, DATA!$A:$A, $A40, DATA!$B:$B, $B40 ) / 100, 0) -> 0 | D40: =INPUT!$E$2 -> 2025
C41: =IFERROR( SUMIFS( DATA!$E:$E, DATA!$A:$A, $A41, DATA!$B:$B, $B41 ) / 100, 0) -> 0 | D41: =INPUT!$E$2 -> 2025
C42: =IFERROR( SUMIFS( DATA!$E:$E, DATA!$A:$A, $A42, DATA!$B:$B, $B42 ) / 100, 0) -> 0 | D42: =INPUT!$E$2 -> 2025
... C50: =IFERROR( SUMIFS( DATA!$E:$E, DATA!$A:$A, $A50, DATA!$B:$B, $B50 ) / 100, 0) -> 0 | D50: =INPUT!$E$2 -> 2025

Sheet DATA
A1: EmployeeName | B1: Month | C1: KPI_Name | D1: Weight | E1: KPI_% | F1: Evaluator | G1: Nots
A2: ايهاب محمد خميس حمد | B2: Jan | C2: معرفة وتطبيق اللوائح والقوانين (قانون العمل والضمان) | D2: 10 | E2: 10 | F2: زياد المعايعة
A3: ايهاب محمد خميس حمد | B3: Jan | C3: إدارة وتنظيم الملفات والسجلات وسهولة الرجوع إليها | D3: 9 | E3: 9 | F3: زياد المعايعة
A4: ايهاب محمد خميس حمد | B4: Jan | C4: السرعة والدقة والإنتاجية في إنجاز العمل | D4: 9 | E4: 9 | F4: زياد المعايعة
A5: ايهاب محمد خميس حمد | B5: Jan | C5: التحليل وإعداد التقارير بدقة واحترافية | D5: 8 | E5: 8 | F5: زياد المعايعة
A6: ايهاب محمد خميس حمد | B6: Jan | C6: الالتزام بأخلاقيات العمل والحياد والمسؤولية | D6: 8 | E6: 8 | F6: زياد المعايعة
A7: ايهاب محمد خميس حمد | B7: Jan | C7: الالتزام بمتطلبات السلامة العامة داخل بيئة العمل | D7: 7 | E7: 7 | F7: زياد المعايعة
A8: ايهاب محمد خميس حمد | B8: Jan | C8: المبادرة واقتراح التحسينات وحل المشكلات | D8: 8 | E8: 8 | F8: زياد المعايعة
A9: ايهاب محمد خميس حمد | B9: Jan | C9: التواصل الفعّال والتعامل المهني (رؤساء، زملاء، عملاء، موظفين جدد) | D9: 7 | E9: 7 | F9: زياد المعايعة
A10: ايهاب محمد خميس حمد | B10: Jan | C10: تحمل ضغط العمل وتنظيم الأولويات وتحمل النتائج | D10: 7 | E10: 7 | F10: زياد المعايعة
A11: ايهاب محمد خميس حمد | B11: Jan | C11: نقل المعرفة وتدريب الآخرين ودعم الفريق | D11: 7 | E11: 7 | F11: زياد المعايعة

Sheet تنبيه
A1: تنبيه!! هذا الملف محمي من قبل مالك التطبيق (شركة رمز لنقل النفط الخام عمان -الاردن) ضمن حقوق النشر والملكية الفكرية وتحت طائلة المسؤولية للمزيد يرجى الاتصال على 0772607814

Sheet YEARLY_SUMMARY
A1: EmployeeName | B1: Year | C1: Yearly_Average | D1: Verbal_Evaluation
A2: عمر ناصر محمد يسري فنون | B2: =INPUT!$E$2 -> 2025 | C2: =IFERROR( AVERAGEIFS( AUTO_MONTHLY!$C:$C, AUTO_MONTHLY!$A:$A, $A2, AUTO_MONTHLY!$C:$C, ">0" ), 0) -> 0 | D2: =IF(C2=0,"", IF(C2*100<60,"ضعيف", IF(C2*100<70,"متوسط", IF(C2*100<80,"جيد", IF(C2*100<90,"جيد جدا", "ممتاز")))))
A3: فايز احمد موسى اصليح | B3: =INPUT!$E$2 -> 2025 | C3: =IFERROR( AVERAGEIFS( AUTO_MONTHLY!$C:$C, AUTO_MONTHLY!$A:$A, $A3, AUTO_MONTHLY!$C:$C, ">0" ), 0) -> 0 | D3: =IF(C3=0,"", IF(C3*100<60,"ضعيف", IF(C3*100<70,"متوسط", IF(C3*100<80,"جيد", IF(C3*100<90,"جيد جدا", "ممتاز")))))
A4: ايهاب محمد خميس حمد | B4: =INPUT!$E$2 -> 2025 | C4: =IFERROR( AVERAGEIFS( AUTO_MONTHLY!$C:$C, AUTO_MONTHLY!$A:$A, $A4, AUTO_MONTHLY!$C:$C, ">0" ), 0) -> 0.8 | D4: =IF(C4=0,"", IF(C4*100<60,"ضعيف", IF(C4*100<70,"متوسط", IF(C4*100<80,"جيد", IF(C4*100<90,"جيد جدا", "ممتاز"))))) -> جيد جدا
A5: خلدون عامر حامد الكسيح | B5: =INPUT!$E$2 -> 2025 | C5: =IFERROR( AVERAGEIFS( AUTO_MONTHLY!$C:$C, AUTO_MONTHLY!$A:$A, $A5, AUTO_MONTHLY!$C:$C, ">0" ), 0) -> 0 | D5: =IF(C5=0,"", IF(C5*100<60,"ضعيف", IF(C5*100<70,"متوسط", IF(C5*100<80,"جيد", IF(C5*100<90,"جيد جدا", "ممتاز")))))
B6: =INPUT!$E$2 -> 2025 | C6: =IFERROR( AVERAGEIFS( AUTO_MONTHLY!$C:$C, AUTO_MONTHLY!$A:$A, $A6, AUTO_MONTHLY!$C:$C, ">0" ), 0) -> 0 | D6: =IF(C6=0,"", IF(C6*100<60,"ضعيف", IF(C6*100<70,"متوسط", IF(C6*100<80,"جيد", IF(C6*100<90,"جيد جدا", "ممتاز")))))
B7: =INPUT!$E$2 -> 2025 | C7: =IFERROR( AVERAGEIFS( AUTO_MONTHLY!$C:$C, AUTO_MONTHLY!$A:$A, $A7, AUTO_MONTHLY!$C:$C, ">0" ), 0) -> 0 | D7: =IF(C7=0,"", IF(C7*100<60,"ضعيف", IF(C7*100<70,"متوسط", IF(C7*100<80,"جيد", IF(C7*100<90,"جيد جدا", "ممتاز")))))
B8: =INPUT!$E$2 -> 2025 | C8: =IFERROR( AVERAGEIFS( AUTO_MONTHLY!$C:$C, AUTO_MONTHLY!$A:$A, $A8, AUTO_MONTHLY!$C:$C, ">0" ), 0) -> 0 | D8: =IF(C8=0,"", IF(C8*100<60,"ضعيف", IF(C8*100<70,"متوسط", IF(C8*100<80,"جيد", IF(C8*100<90,"جيد جدا", "ممتاز")))))
B9: =INPUT!$E$2 -> 2025 | C9: =IFERROR( AVERAGEIFS( AUTO_MONTHLY!$C:$C, AUTO_MONTHLY!$A:$A, $A9, AUTO_MONTHLY!$C:$C, ">0" ), 0) -> 0 | D9: =IF(C9=0,"", IF(C9*100<60,"ضعيف", IF(C9*100<70,"متوسط", IF(C9*100<80,"جيد", IF(C9*100<90,"جيد جدا", "ممتاز")))))
B10: =INPUT!$E$2 -> 2025 | C10: =IFERROR( AVERAGEIFS( AUTO_MONTHLY!$C:$C, AUTO_MONTHLY!$A:$A, $A10, AUTO_MONTHLY!$C:$C, ">0" ), 0) -> 0 | D10: =IF(C10=0,"", IF(C10*100<60,"ضعيف", IF(C10*100<70,"متوسط", IF(C10*100<80,"جيد", IF(C10*100<90,"جيد جدا", "ممتاز")))))
B11: =INPUT!$E$2 -> 2025 | C11: =IFERROR( AVERAGEIFS( AUTO_MONTHLY!$C:$C, AUTO_MONTHLY!$A:$A, $A11, AUTO_MONTHLY!$C:$C, ">0" ), 0) -> 0 | D11: =IF(C11=0,"", IF(C11*100<60,"ضعيف", IF(C11*100<70,"متوسط", IF(C11*100<80,"جيد", IF(C11*100<90,"جيد جدا", "ممتاز")))))
B12: =INPUT!$E$2 -> 2025 | C12: =IFERROR( AVERAGEIFS( AUTO_MONTHLY!$C:$C, AUTO_MONTHLY!$A:$A, $A12, AUTO_MONTHLY!$C:$C, ">0" ), 0) -> 0 | D12: =IF(C12=0,"", IF(C12*100<60,"ضعيف", IF(C12*100<70,"متوسط", IF(C12*100<80,"جيد", IF(C12*100<90,"جيد جدا", "ممتاز")))))
B13: =INPUT!$E$2 -> 2025 | C13: =IFERROR( AVERAGEIFS( AUTO_MONTHLY!$C:$C, AUTO_MONTHLY!$A:$A, $A13, AUTO_MONTHLY!$C:$C, ">0" ), 0) -> 0 | D13: =IF(C13=0,"", IF(C13*100<60,"ضعيف", IF(C13*100<70,"متوسط", IF(C13*100<80,"جيد", IF(C13*100<90,"جيد جدا", "ممتاز")))))
B14: =INPUT!$E$2 -> 2025 | C14: =IFERROR( AVERAGEIFS( AUTO_MONTHLY!$C:$C, AUTO_MONTHLY!$A:$A, $A14, AUTO_MONTHLY!$C:$C, ">0" ), 0) -> 0 | D14: =IF(C14=0,"", IF(C14*100<60,"ضعيف", IF(C14*100<70,"متوسط", IF(C14*100<80,"جيد", IF(C14*100<90,"جيد جدا", "ممتاز")))))
B15: =INPUT!$E$2 -> 2025 | C15: =IFERROR( AVERAGEIFS( AUTO_MONTHLY!$C:$C, AUTO_MONTHLY!$A:$A, $A15, AUTO_MONTHLY!$C:$C, ">0" ), 0) -> 0 | D15: =IF(C15=0,"", IF(C15*100<60,"ضعيف", IF(C15*100<70,"متوسط", IF(C15*100<80,"جيد", IF(C15*100<90,"جيد جدا", "ممتاز")))))
B16: =INPUT!$E$2 -> 2025 | C16: =IFERROR( AVERAGEIFS( AUTO_MONTHLY!$C:$C, AUTO_MONTHLY!$A:$A, $A16, AUTO_MONTHLY!$C:$C, ">0" ), 0) -> 0 | D16: =IF(C16=0,"", IF(C16*100<60,"ضعيف", IF(C16*100<70,"متوسط", IF(C16*100<80,"جيد", IF(C16*100<90,"جيد جدا", "ممتاز")))))
B17: =INPUT!$E$2 -> 2025 | C17: =IFERROR( AVERAGEIFS( AUTO_MONTHLY!$C:$C, AUTO_MONTHLY!$A:$A, $A17, AUTO_MONTHLY!$C:$C, ">0" ), 0) -> 0 | D17: =IF(C17=0,"", IF(C17*100<60,"ضعيف", IF(C17*100<70,"متوسط", IF(C17*100<80,"جيد", IF(C17*100<90,"جيد جدا", "ممتاز")))))
... B31: =INPUT!$E$2 -> 2025 | C31: =IFERROR( AVERAGEIFS( AUTO_MONTHLY!$C:$C, AUTO_MONTHLY!$A:$A, $A31, AUTO_MONTHLY!$C:$C, ">0" ), 0) -> 0 | D31: =IF(C31=0,"", IF(C31*100<60,"ضعيف", IF(C31*100<70,"متوسط", IF(C31*100<80,"جيد", IF(C31*100<90,"جيد جدا", "ممتاز")))))
B32: =INPUT!$E$2 -> 2025 | C32: =IFERROR( AVERAGEIFS( AUTO_MONTHLY!$C:$C, AUTO_MONTHLY!$A:$A, $A32, AUTO_MONTHLY!$C:$C, ">0" ), 0) -> 0
B33: =INPUT!$E$2 -> 2025 | C33: =IFERROR( AVERAGEIFS( AUTO_MONTHLY!$C:$C, AUTO_MONTHLY!$A:$A, $A33, AUTO_MONTHLY!$C:$C, ">0" ), 0) -> 0
B34: =INPUT!$E$2 -> 2025 | C34: =IFERROR( AVERAGEIFS( AUTO_MONTHLY!$C:$C, AUTO_MONTHLY!$A:$A, $A34, AUTO_MONTHLY!$C:$C, ">0" ), 0) -> 0
B35: =INPUT!$E$2 -> 2025 | C35: =IFERROR( AVERAGEIFS( AUTO_MONTHLY!$C:$C, AUTO_MONTHLY!$A:$A, $A35, AUTO_MONTHLY!$C:$C, ">0" ), 0) -> 0
B36: =INPUT!$E$2 -> 2025 | C36: =IFERROR( AVERAGEIFS( AUTO_MONTHLY!$C:$C, AUTO_MONTHLY!$A:$A, $A36, AUTO_MONTHLY!$C:$C, ">0" ), 0) -> 0
B37: =INPUT!$E$2 -> 2025 | C37: =IFERROR( AVERAGEIFS( AUTO_MONTHLY!$C:$C, AUTO_MONTHLY!$A:$A, $A37, AUTO_MONTHLY!$C:$C, ">0" ), 0) -> 0
B38: =INPUT!$E$2 -> 2025 | C38: =IFERROR( AVERAGEIFS( AUTO_MONTHLY!$C:$C, AUTO_MONTHLY!$A:$A, $A38, AUTO_MONTHLY!$C:$C, ">0" ), 0) -> 0
B39: =INPUT!$E$2 -> 2025 | C39: =IFERROR( AVERAGEIFS( AUTO_MONTHLY!$C:$C, AUTO_MONTHLY!$A:$A, $A39, AUTO_MONTHLY!$C:$C, ">0" ), 0) -> 0
B40: =INPUT!$E$2 -> 2025 | C40: =IFERROR( AVERAGEIFS( AUTO_MONTHLY!$C:$C, AUTO_MONTHLY!$A:$A, $A40, AUTO_MONTHLY!$C:$C, ">0" ), 0) -> 0
B41: =INPUT!$E$2 -> 2025 | C41: =IFERROR( AVERAGEIFS( AUTO_MONTHLY!$C:$C, AUTO_MONTHLY!$A:$A, $A41, AUTO_MONTHLY!$C:$C, ">0" ), 0) -> 0
B42: =INPUT!$E$2 -> 2025 | C42: =IFERROR( AVERAGEIFS( AUTO_MONTHLY!$C:$C, AUTO_MONTHLY!$A:$A, $A42, AUTO_MONTHLY!$C:$C, ">0" ), 0) -> 0

Sheet نموذج التقييم النهائي
D2: ="تقييم الأداء السنوي للموظف–" & B4 & CHAR(10) & "النتيجة: " & TEXT(B11*100,"0") & "% (" & B12 & ")" -> تقييم الأداء السنوي للموظف–ايهاب محمد خميس حمد النتيجة: 80% (جيد جداً)
A4: اسم الموظف | B4: ايهاب محمد خميس حمد
A5: الوظيفة | B5: =IFERROR(_xlfn.XLOOKUP($B$4,EMPLOYEES!$A:$A,EMPLOYEES!$B:$B),"") -> منسق موارد بشرية
A6: القسم | B6: =INPUT!B5 -> الموارد البشرية
A7: السنة | B7: =INPUT!$E$2 -> 2025
A8: اسم المقيم | B8: =INPUT!B4 -> زياد المعايعة
A9: تاريخ التقييم | B9: =TODAY() -> 46135
A10: نتيجة التقييم
A11: التقييم السنوي | B11: =IFERROR(AVERAGEIFS(AUTO_MONTHLY!$C:$C,AUTO_MONTHLY!$A:$A,$B$4,AUTO_MONTHLY!$C:$C,">0"),0) -> 0.8
A12: نتيجة التقييم | B12: =IF(B11=0,"", IF(B11*100<60,"ضعيف", IF(B11*100<70,"متوسط", IF(B11*100<80,"جيد", IF(B11*100<90,"جيد جداً", "ممتاز"))))) -> جيد جداً
A13: عدد الأشهر التي تم تقييمها | B13: =COUNTIFS(AUTO_MONTHLY!$A:$A,$B$4,AUTO_MONTHLY!$C:$C,">0") -> 1
A16: المؤشر | B16: الوزن | C16: متوسط المؤشر (KPI_%) السنوي | E16: # | F16: الشهر | G16: التقييم الشهري
A17: {=IFERROR( INDEX(KPIs!$B:$B, SMALL( IF(KPIs!$A:$A=$B$5, ROW(KPIs!$B:$B)), ROW(A1) ) ), "")} -> معرفة وتطبيق اللوائح والقوانين (قانون العمل والضمان) | B17: {=IFERROR( _xlfn.XLOOKUP(_xlfn.ANCHORARRAY( A17), KPIs!$B:$B, KPIs!$C:$C ), 0)} -> 10 | C17: {=IFERROR( _xlfn.BYROW(_xlfn.ANCHORARRAY( A17), _xlfn.LAMBDA(_xlpm.k, AVERAGEIFS( DATA!$E:$E, DATA!$A:$A,$B$4, DATA!$C:$C,_xlpm.k ) ) ), 0)} -> 10 | E17: 1 | F17: Jan | G17: {=IFERROR(_xlfn._xlws.FILTER(AUTO_MONTHLY!$C:$C,(AUTO_MONTHLY!$A:$A=$B$4)*(AUTO_MONTHLY!$C:$C>0)),"")} -> 0.8
A18: {=IFERROR( INDEX(KPIs!$B:$B, SMALL( IF(KPIs!$A:$A=$B$5, ROW(KPIs!$B:$B)), ROW(A2) ) ), "")} -> إدارة وتنظيم الملفات والسجلات وسهولة الرجوع إليها | B18: {=IFERROR( _xlfn.XLOOKUP(_xlfn.ANCHORARRAY( A18), KPIs!$B:$B, KPIs!$C:$C ), 0)} -> 9 | C18: =IFERROR(AVERAGEIFS(DATA!$E:$E,DATA!$A:$A,$B$4,DATA!$C:$C,$A18),0) -> 9 | E18: 2 | F18: Feb
A19: {=IFERROR( INDEX(KPIs!$B:$B, SMALL( IF(KPIs!$A:$A=$B$5, ROW(KPIs!$B:$B)), ROW(A3) ) ), "")} -> السرعة والدقة والإنتاجية في إنجاز العمل | B19: {=IFERROR( _xlfn.XLOOKUP(_xlfn.ANCHORARRAY( A19), KPIs!$B:$B, KPIs!$C:$C ), 0)} -> 9 | C19: =IFERROR(AVERAGEIFS(DATA!$E:$E,DATA!$A:$A,$B$4,DATA!$C:$C,$A19),0) -> 9 | E19: 3 | F19: Mar
A20: {=IFERROR( INDEX(KPIs!$B:$B, SMALL( IF(KPIs!$A:$A=$B$5, ROW(KPIs!$B:$B)), ROW(A4) ) ), "")} -> التحليل وإعداد التقارير بدقة واحترافية | B20: {=IFERROR( _xlfn.XLOOKUP(_xlfn.ANCHORARRAY( A20), KPIs!$B:$B, KPIs!$C:$C ), 0)} -> 8 | C20: =IFERROR(AVERAGEIFS(DATA!$E:$E,DATA!$A:$A,$B$4,DATA!$C:$C,$A20),0) -> 8 | E20: 4 | F20: Apr
A21: {=IFERROR( INDEX(KPIs!$B:$B, SMALL( IF(KPIs!$A:$A=$B$5, ROW(KPIs!$B:$B)), ROW(A5) ) ), "")} -> الالتزام بأخلاقيات العمل والحياد والمسؤولية | B21: {=IFERROR( _xlfn.XLOOKUP(_xlfn.ANCHORARRAY( A21), KPIs!$B:$B, KPIs!$C:$C ), 0)} -> 8 | C21: =IFERROR(AVERAGEIFS(DATA!$E:$E,DATA!$A:$A,$B$4,DATA!$C:$C,$A21),0) -> 8 | E21: 5 | F21: May
A22: {=IFERROR( INDEX(KPIs!$B:$B, SMALL( IF(KPIs!$A:$A=$B$5, ROW(KPIs!$B:$B)), ROW(A6) ) ), "")} -> الالتزام بمتطلبات السلامة العامة داخل بيئة العمل | B22: {=IFERROR( _xlfn.XLOOKUP(_xlfn.ANCHORARRAY( A22), KPIs!$B:$B, KPIs!$C:$C ), 0)} -> 7 | C22: =IFERROR(AVERAGEIFS(DATA!$E:$E,DATA!$A:$A,$B$4,DATA!$C:$C,$A22),0) -> 7 | E22: 6 | F22: Jun
A23: {=IFERROR( INDEX(KPIs!$B:$B, SMALL( IF(KPIs!$A:$A=$B$5, ROW(KPIs!$B:$B)), ROW(A7) ) ), "")} -> المبادرة واقتراح التحسينات وحل المشكلات | B23: {=IFERROR( _xlfn.XLOOKUP(_xlfn.ANCHORARRAY( A23), KPIs!$B:$B, KPIs!$C:$C ), 0)} -> 8 | C23: =IFERROR(AVERAGEIFS(DATA!$E:$E,DATA!$A:$A,$B$4,DATA!$C:$C,$A23),0) -> 8 | E23: 7 | F23: Jul
A24: {=IFERROR( INDEX(KPIs!$B:$B, SMALL( IF(KPIs!$A:$A=$B$5, ROW(KPIs!$B:$B)), ROW(A8) ) ), "")} -> التواصل الفعّال والتعامل المهني (رؤساء، زملاء، عملاء، موظفين جدد) | B24: {=IFERROR( _xlfn.XLOOKUP(_xlfn.ANCHORARRAY( A24), KPIs!$B:$B, KPIs!$C:$C ), 0)} -> 7 | C24: =IFERROR(AVERAGEIFS(DATA!$E:$E,DATA!$A:$A,$B$4,DATA!$C:$C,$A24),0) -> 7 | E24: 8 | F24: Aug
A25: {=IFERROR( INDEX(KPIs!$B:$B, SMALL( IF(KPIs!$A:$A=$B$5, ROW(KPIs!$B:$B)), ROW(A9) ) ), "")} -> تحمل ضغط العمل وتنظيم الأولويات وتحمل النتائج | B25: {=IFERROR( _xlfn.XLOOKUP(_xlfn.ANCHORARRAY( A25), KPIs!$B:$B, KPIs!$C:$C ), 0)} -> 7 | C25: =IFERROR(AVERAGEIFS(DATA!$E:$E,DATA!$A:$A,$B$4,DATA!$C:$C,$A25),0) -> 7 | E25: 9 | F25: Sep
A26: {=IFERROR( INDEX(KPIs!$B:$B, SMALL( IF(KPIs!$A:$A=$B$5, ROW(KPIs!$B:$B)), ROW(A10) ) ), "")} -> نقل المعرفة وتدريب الآخرين ودعم الفريق | B26: {=IFERROR( _xlfn.XLOOKUP(_xlfn.ANCHORARRAY( A26), KPIs!$B:$B, KPIs!$C:$C ), 0)} -> 7 | C26: =IFERROR(AVERAGEIFS(DATA!$E:$E,DATA!$A:$A,$B$4,DATA!$C:$C,$A26),0) -> 7 | E26: 10 | F26: Oct
A27: ملاحظات خاصة بالمقيم : | E27: 11 | F27: Nov
E28: 12 | F28: Dec
A29: الاحتياجات التدريبية للموظف : 1- 2- 3- | D29: ملاحظة : لاتمام استخراج نموذج التقييم النهائي يجب على المقيم تعبئة التقييم بشكل شهري من قائمة INPUT ثم في قائمة AUTO-MONTHLY
A32: المسؤول المباشر | B32: =B8 -> زياد المعايعة | C32: اسم الموظف | D32: =B4 -> ايهاب محمد خميس حمد
A33: توقيع المسؤول المباشر | C33: التوقيع
